2025-01-09 16:40:17,014 | INFO    | 
Testing with concurrency level: 1
2025-01-09 16:40:17,014 | INFO    | Starting performance test with concurrency level: 1
2025-01-09 16:40:17,233 | ERROR   | API request failed: HTTPConnectionPool(host='localhost', port=8050): Max retries exceeded with url: /direct_analysis (Caused by NewConnectionError('<urllib3.connection.HTTPConnection object at 0x10b8cb910>: Failed to establish a new connection: [Errno 61] Connection refused'))
2025-01-09 16:40:17,234 | ERROR   | Request failed: 'StatefulTraceClient' object has no attribute 'end'
2025-01-09 16:40:17,335 | ERROR   | Performance test failed: 'StatefulTraceClient' object has no attribute 'end'
2025-01-09 16:42:05,709 | INFO    | 
Testing with concurrency level: 1
2025-01-09 16:42:05,709 | INFO    | Starting performance test with concurrency level: 1
2025-01-09 16:42:05,922 | ERROR   | API request failed: HTTPConnectionPool(host='localhost', port=8050): Max retries exceeded with url: /direct_analysis (Caused by NewConnectionError('<urllib3.connection.HTTPConnection object at 0x10832c9a0>: Failed to establish a new connection: [Errno 61] Connection refused'))
2025-01-09 16:42:05,923 | ERROR   | Request failed: 'StatefulTraceClient' object has no attribute 'update_metadata'
2025-01-09 16:42:06,028 | ERROR   | Concurrent test failed: 'StatefulTraceClient' object has no attribute 'update_metadata'
2025-01-09 16:42:06,031 | ERROR   | Performance test failed: 'StatefulTraceClient' object has no attribute 'update_metadata'
